#VRML_SIM R2025a utf8

# SAFESORT_LAYOUT workspace_mm=10000,6000
# SAFESORT_LAYOUT a_anchor_mm=1000,3000
# SAFESORT_LAYOUT b_anchor_mm=8000,3800
# SAFESORT_LAYOUT c_center_mm=7000,1200 c_size_mm=1200,800,800
# SAFESORT_LAYOUT d_center_mm=8500,1200 d_size_mm=1200,800,800

WorldInfo {
  info [
    "SafeSort deterministic unknown-STL smoke world"
  ]
  basicTimeStep 32
  coordinateSystem "NUE"
}
Viewpoint {
  orientation -0.364 0.872 0.327 1.645
  position 5.35 8.65 8.95
}
DirectionalLight {
  direction -0.3 -1 -0.2
  intensity 1.2
}

DEF WORKSPACE Solid {
  translation 0 -0.05 0
  name "official_workspace_10000x6000"
  children [
    Shape {
      appearance PBRAppearance {
        baseColor 0.72 0.74 0.76
        roughness 1
        metalness 0
      }
      geometry Box {
        size 10 0.1 6
      }
    }
  ]
  boundingObject Box {
    size 10 0.1 6
  }
}

DEF A_ANCHOR Transform {
  translation -4 0.7 0
  children [
    Shape {
      appearance PBRAppearance { baseColor 0.9 0.6 0.1 }
      geometry Sphere { radius 0.04 }
    }
  ]
}
DEF B_ANCHOR Transform {
  translation 3 0.7 0.8
  children [
    Shape {
      appearance PBRAppearance { baseColor 0.1 0.8 0.2 }
      geometry Sphere { radius 0.04 }
    }
  ]
}

DEF MAIN_BELT Solid {
  translation -1.25 0.64 0
  name "main_belt"
  children [
    Shape {
      appearance PBRAppearance {
        baseColor 0.025 0.025 0.025
        roughness 1
      }
      geometry Box { size 5.5 0.12 0.5 }
    }
  ]
  boundingObject Box { size 5.5 0.12 0.5 }
}
DEF B_BRANCH Solid {
  translation 2.25 0.64 0.4
  rotation 0 1 0 -0.49
  name "b_branch"
  children [
    Shape {
      appearance PBRAppearance { baseColor 0.025 0.025 0.025 roughness 1 }
      geometry Box { size 1.7 0.12 0.5 }
    }
  ]
  boundingObject Box { size 1.7 0.12 0.5 }
}
DEF B_CONVEYOR Solid {
  translation 3 0.64 1.4
  name "b_conveyor"
  children [
    Shape {
      appearance PBRAppearance { baseColor 0.025 0.025 0.025 roughness 1 }
      geometry Box { size 0.5 0.12 1.2 }
    }
  ]
  boundingObject Box { size 0.5 0.12 1.2 }
}

DEF C_CAGE Solid {
  translation 2 0.4 -1.8
  name "c_cage_1200x800x800"
  children [
    Shape {
      appearance PBRAppearance { baseColor 0.05 0.35 0.9 roughness 0.6 }
      geometry Box { size 1.2 0.05 0.8 }
    }
  ]
  boundingObject Box { size 1.2 0.8 0.8 }
}
DEF D_CAGE Solid {
  translation 3.5 0.4 -1.8
  name "d_cage_1200x800x800"
  children [
    Shape {
      appearance PBRAppearance { baseColor 0.05 0.35 0.9 roughness 0.6 }
      geometry Box { size 1.2 0.05 0.8 }
    }
  ]
  boundingObject Box { size 1.2 0.8 0.8 }
}

Robot {
  name "RuntimeController"
  controller "runtime_controller"
  children [
    RangeFinder {
      translation -3.5 2 0
      rotation 0 0 1 -1.5708
      name "rangefinder_top"
      fieldOfView 0.5
      width 96
      height 96
      minRange 0.1
      maxRange 2
      noise 0
    }
    DistanceSensor {
      translation -3.8 0.75 0
      name "photoeye_entry"
      type "laser"
      lookupTable [ 0 0 0, 0.7 0.7 0 ]
    }
    DistanceSensor {
      translation 3.3 0.75 1.1
      rotation 0 1 0 3.14159
      name "b_exit_sensor"
      type "laser"
      lookupTable [ 0 0 0, 0.7 0.7 0 ]
    }
    Emitter {
      name "runtime_events_emitter"
      channel 17
    }
    HingeJoint {
      jointParameters HingeJointParameters {
        axis 0 1 0
        anchor 0.5 0.8 0
      }
      device [
        RotationalMotor {
          name "provisional_gate_motor"
          minPosition 0
          maxPosition 1.5708
          maxVelocity 8
          maxTorque 20
          sound ""
        }
        PositionSensor {
          name "provisional_gate_position"
        }
      ]
      endPoint Solid {
        translation 0.5 0.8 0
        children [
          Shape {
            appearance PBRAppearance { baseColor 0.95 0.55 0.1 roughness 0.5 }
            geometry Box { size 0.04 0.25 0.5 }
          }
        ]
        boundingObject Box { size 0.04 0.25 0.5 }
        physics Physics { density -1 mass 1 }
      }
    }
  ]
}

Robot {
  supervisor TRUE
  name "EvaluatorSupervisor"
  controller "evaluator_supervisor"
  children [
    Receiver {
      name "runtime_events_receiver"
      channel 17
    }
  ]
}

DEF ANON_ITEM Solid {
  translation -3.5 0.73 0
  name "fixture-7f3a"
  children [
    Shape {
      appearance PBRAppearance {
        baseColor 0.85 0.1 0.08
        roughness 0.75
      }
      geometry Mesh {
        url [
          "../../assets/smoke/anonymous_box.stl"
        ]
      }
    }
  ]
  boundingObject Box { size 0.12 0.05 0.06 }
  physics Physics {
    density -1
    mass 1
  }
}
