#VRML_SIM R2025a utf8

PROTO SorterCell [
  field SFString expectedRoute "B"
  field MFString itemMeshUrl [
    "../../assets/smoke/anonymous_box.stl"
  ]
  field SFVec3f itemScale 1 1 1
  field SFVec3f itemBoundingSize 0.12 0.05 0.06
] {
  Group {
    children [
      DEF WORKSPACE Solid {
        translation 0 -0.05 0
        name "official_workspace_10000x6000"
        children [
          Shape {
            appearance PBRAppearance { baseColor 0.72 0.74 0.76 roughness 1 metalness 0 }
            geometry Box { size 10 0.1 6 }
          }
        ]
        boundingObject Box { size 10 0.1 6 }
      }
      DEF A_ANCHOR Transform {
        translation -4 0.7 0
        children [
          Shape {
            appearance PBRAppearance { baseColor 0.9 0.6 0.1 }
            geometry Sphere { radius 0.04 }
          }
        ]
      }
      DEF B_ANCHOR Transform {
        translation 3 0.7 0.8
        children [
          Shape {
            appearance PBRAppearance { baseColor 0.1 0.8 0.2 }
            geometry Sphere { radius 0.04 }
          }
        ]
      }
      DEF C_CAGE Solid {
        translation 2 0.37 -1.8
        name "c_cage_1200x800x800"
        children [
          Shape {
            appearance PBRAppearance { baseColor 0.05 0.35 0.9 roughness 0.6 transparency 0.2 }
            geometry Box { size 1.2 0.04 0.8 }
          }
        ]
        boundingObject Box { size 1.2 0.04 0.8 }
      }
      DEF D_CAGE Solid {
        translation 3.5 0.37 -1.8
        name "d_cage_1200x800x800"
        children [
          Shape {
            appearance PBRAppearance { baseColor 0.18 0.25 0.82 roughness 0.6 transparency 0.2 }
            geometry Box { size 1.2 0.04 0.8 }
          }
        ]
        boundingObject Box { size 1.2 0.04 0.8 }
      }
      Robot {
        name "RuntimeController"
        controller "runtime_controller"
        children [
          Solid {
            translation -0.35 0.61 0
            children [
              Shape {
                appearance PBRAppearance { baseColor 0.18 0.2 0.24 roughness 0.8 }
                geometry Box { size 6.5 0.12 0.58 }
              }
            ]
            boundingObject Box { size 6.5 0.12 0.58 }
          }
          Track {
            translation -0.35 0.69 0
            rotation 1 0 0 -1.5708
            name "physical_main_track"
            contactMaterial "safesort_belt"
            children [
              DEF MAIN_TRACK_SHAPE Shape {
                appearance PBRAppearance { baseColor 0.035 0.04 0.05 roughness 0.9 metalness 0 }
                geometry Box { size 6.5 0.50 0.025 }
              }
            ]
            boundingObject USE MAIN_TRACK_SHAPE
            physics Physics { density -1 mass 30 }
            device [
              LinearMotor {
                name "main_track_motor"
                maxVelocity 1.2
                maxForce 180
              }
            ]
            animatedGeometry Shape {
              appearance PBRAppearance { baseColor 0.12 0.14 0.18 roughness 0.8 }
              geometry Box { size 0.08 0.50 0.012 }
            }
            geometriesCount 60
          }
          Pose {
            translation 0.95 0.69 -1.125
            rotation 0 1 0 0.594
            children [
              Track {
                rotation 1 0 0 -1.5708
                name "physical_c_track"
                contactMaterial "safesort_belt"
                children [
                  DEF C_TRACK_SHAPE Shape {
                    appearance PBRAppearance { baseColor 0.06 0.25 0.56 roughness 0.9 }
                    geometry Box { size 2.45 0.48 0.025 }
                  }
                ]
                boundingObject USE C_TRACK_SHAPE
                physics Physics { density -1 mass 14 }
                device [
                  LinearMotor { name "c_track_motor" maxVelocity 1.2 maxForce 140 }
                ]
              }
            ]
          }
          Pose {
            translation 2.525 0.69 -1.05
            rotation 0 1 0 0.632
            children [
              Track {
                rotation 1 0 0 -1.5708
                name "physical_d_track"
                contactMaterial "safesort_belt"
                children [
                  DEF D_TRACK_SHAPE Shape {
                    appearance PBRAppearance { baseColor 0.16 0.20 0.62 roughness 0.9 }
                    geometry Box { size 2.55 0.48 0.025 }
                  }
                ]
                boundingObject USE D_TRACK_SHAPE
                physics Physics { density -1 mass 16 }
                device [
                  LinearMotor { name "d_track_motor" maxVelocity 1.2 maxForce 140 }
                ]
              }
            ]
          }
          Pose {
            translation 2.65 0.69 0.4
            rotation 0 1 0 -0.675
            children [
              Track {
                rotation 1 0 0 -1.5708
                name "physical_b_track"
                contactMaterial "safesort_belt"
                children [
                  DEF B_TRACK_SHAPE Shape {
                    appearance PBRAppearance { baseColor 0.05 0.38 0.20 roughness 0.9 }
                    geometry Box { size 1.35 0.48 0.025 }
                  }
                ]
                boundingObject USE B_TRACK_SHAPE
                physics Physics { density -1 mass 10 }
                device [
                  LinearMotor { name "b_track_motor" maxVelocity 1.2 maxForce 140 }
                ]
              }
            ]
          }
          HingeJoint {
            jointParameters HingeJointParameters {
              axis 0 1 0
              anchor -0.15 0.81 0.28
              minStop -0.98
              maxStop 0
              springConstant 24
              dampingConstant 3.2
              staticFriction 0.04
            }
            device [
              RotationalMotor {
                name "dimension_gate_motor"
                minPosition -0.98
                maxPosition 0
                maxVelocity 3
                maxTorque 32
                sound ""
              }
              PositionSensor { name "dimension_gate_position" }
            ]
            endPoint Solid {
              translation -0.15 0.81 0.28
              rotation 0 1 0 -0.65
              name "dimension_fail_safe_gate_to_C"
              children [
                Pose {
                  translation 0 0 -0.43
                  children [
                    Shape {
                      appearance PBRAppearance { baseColor 0.96 0.44 0.05 roughness 0.5 }
                      geometry DEF DIM_GATE_BOX Box { size 0.045 0.26 0.86 }
                    }
                  ]
                }
              ]
              boundingObject Pose {
                translation 0 0 -0.43
                children [ USE DIM_GATE_BOX ]
              }
              physics Physics { density -1 mass 1.2 }
            }
          }
          HingeJoint {
            jointParameters HingeJointParameters {
              axis 0 1 0
              anchor 1.15 0.81 0.28
              minStop -0.98
              maxStop 0
              springConstant 24
              dampingConstant 3.2
              staticFriction 0.04
            }
            device [
              RotationalMotor {
                name "shape_gate_motor"
                minPosition -0.98
                maxPosition 0
                maxVelocity 3
                maxTorque 32
                sound ""
              }
              PositionSensor { name "shape_gate_position" }
            ]
            endPoint Solid {
              translation 1.15 0.81 0.28
              rotation 0 1 0 -0.65
              name "shape_fail_safe_gate_to_D"
              children [
                Pose {
                  translation 0 0 -0.43
                  children [
                    Shape {
                      appearance PBRAppearance { baseColor 0.98 0.64 0.06 roughness 0.5 }
                      geometry DEF SHAPE_GATE_BOX Box { size 0.045 0.26 0.86 }
                    }
                  ]
                }
              ]
              boundingObject Pose {
                translation 0 0 -0.43
                children [ USE SHAPE_GATE_BOX ]
              }
              physics Physics { density -1 mass 1.2 }
            }
          }
          Solid {
            translation 2.25 0.81 0
            rotation 0 1 0 0.79
            name "passive_b_guide"
            children [
              Shape {
                appearance PBRAppearance { baseColor 0.10 0.65 0.34 roughness 0.55 }
                geometry DEF B_GUIDE_BOX Box { size 0.045 0.25 0.70 }
              }
            ]
            boundingObject USE B_GUIDE_BOX
          }
          Pose {
            translation -3.5 2 0
            rotation 1 0 0 -1.5708
            children [
              RangeFinder {
                # Webots camera coordinates are adapted to canonical image-right,
                # image-up, optical -Z before applying the calibrated world pose.
                rotation -0.577350269 0.577350269 0.577350269 2.094395102
                name "rangefinder_top"
                fieldOfView 0.5
                width 96
                height 96
                minRange 0.1
                maxRange 2
                noise 0
              }
            ]
          }
          Pose {
            translation -3.5 0.8 -0.8
            rotation 0 1 0 3.14159
            children [
              RangeFinder {
                rotation -0.577350269 0.577350269 0.577350269 2.094395102
                name "rangefinder_left"
                fieldOfView 0.7
                width 64
                height 64
                minRange 0.05
                maxRange 2
                noise 0
              }
            ]
          }
          Pose {
            translation -3.5 0.8 0.8
            children [
              RangeFinder {
                rotation -0.577350269 0.577350269 0.577350269 2.094395102
                name "rangefinder_right"
                fieldOfView 0.7
                width 64
                height 64
                minRange 0.05
                maxRange 2
                noise 0
              }
            ]
          }
          Pose {
            translation -4.2 0.8 0
            rotation 0 1 0 -1.5708
            children [
              RangeFinder {
                rotation -0.577350269 0.577350269 0.577350269 2.094395102
                name "rangefinder_front"
                fieldOfView 0.7
                width 256
                height 256
                minRange 0.05
                maxRange 2
                noise 0
              }
            ]
          }
          Pose {
            translation -2.8 0.8 0
            rotation 0 1 0 1.5708
            children [
              RangeFinder {
                rotation -0.577350269 0.577350269 0.577350269 2.094395102
                name "rangefinder_rear"
                fieldOfView 0.7
                width 256
                height 256
                minRange 0.05
                maxRange 2
                noise 0
              }
            ]
          }
          DistanceSensor {
            translation -3.9 0.78 0
            name "photoeye_entry"
            type "laser"
            lookupTable [ 0 0 0, 0.8 0.8 0 ]
          }
          TouchSensor {
            translation 3.15 0.82 0.8
            rotation 0 1 0 -0.675
            name "b_exit_sensor"
            type "force"
            children [
              Shape {
                appearance PBRAppearance { baseColor 0.1 0.8 0.2 roughness 0.5 }
                geometry DEF B_EXIT_CATCHER Box { size 0.045 0.30 0.56 }
              }
            ]
            boundingObject USE B_EXIT_CATCHER
            physics Physics { density -1 mass 0.4 }
          }
          TouchSensor {
            translation 2.05 0.82 -1.8
            rotation 0 1 0 0.594
            name "c_exit_sensor"
            type "force"
            children [
              Shape {
                appearance PBRAppearance { baseColor 0.05 0.35 0.9 roughness 0.5 }
                geometry DEF C_EXIT_CATCHER Box { size 0.045 0.30 0.56 }
              }
            ]
            boundingObject USE C_EXIT_CATCHER
            physics Physics { density -1 mass 0.4 }
          }
          TouchSensor {
            translation 3.55 0.82 -1.8
            rotation 0 1 0 0.632
            name "d_exit_sensor"
            type "force"
            children [
              Shape {
                appearance PBRAppearance { baseColor 0.18 0.25 0.82 roughness 0.5 }
                geometry DEF D_EXIT_CATCHER Box { size 0.045 0.30 0.56 }
              }
            ]
            boundingObject USE D_EXIT_CATCHER
            physics Physics { density -1 mass 0.4 }
          }
          Emitter {
            name "runtime_events_emitter"
            channel 17
          }
        ]
        boundingObject Box { size 0.1 0.1 0.1 }
      }
      Robot {
        supervisor TRUE
        name "EvaluatorSupervisor"
        controller "evaluator_supervisor"
        customData IS expectedRoute
        children [
          Camera {
            translation 0.25 7 -0.4
            rotation 0 0 1 -1.570796327
            name "evidence_camera"
            fieldOfView 1.45
            width 960
            height 540
            near 0.1
            far 20
          }
          Receiver {
            name "runtime_events_receiver"
            channel 17
          }
        ]
      }
      DEF ANON_ITEM Solid {
        translation -3.5 0.73 0
        name "fixture-7f3a"
        contactMaterial "safesort_parcel"
        children [
          Transform {
            scale IS itemScale
            children [
              Shape {
                appearance PBRAppearance { baseColor 0.85 0.1 0.08 roughness 0.75 }
                geometry Mesh { url IS itemMeshUrl }
              }
            ]
          }
        ]
        boundingObject Box { size IS itemBoundingSize }
        physics Physics { density -1 mass 1 }
      }
    ]
  }
}
